Workbook

Sheet Dashboard
A1: 24-Month Goal & Habit Dashboard
A3: Daily habit consistency | B3: =IFERROR(AVERAGE('Daily Tracker'!N2:N366),"") -> 0.79545455
A4: Weekly average score | B4: =IFERROR(AVERAGE('Weekly Review'!I2:I53),"") -> 0.79545455
A5: Monthly average score | B5: =IFERROR(AVERAGE('Monthly Goals'!Q2:Q13),"") -> 25
A7: Core 24-month goals
A8: Career | B8: Move toward AI/ML / Data Engineering role
A9: Skills | B9: Build strong Python, SQL, ML, GenAI, RAG, MLOps & Cloud skills
A10: Fitness | B10: Progress toward 70 kg while improving strength and fitness
A11: Finance | B11: Increase savings, income and financial stability
A12: International | B12: Prepare for future international career opportunities

Sheet Daily Tracker
A1: Date | B1: Day | C1: Study (1.5-2h) | D1: Coding (30-45m) | E1: Workout | F1: ABS + Steps 2k+ | G1: Diet 90% | H1: Water 2.5-3L | I1: English 15m | J1: Finance 5m | K1: Screen <2h | L1: Sleep 6-7h | M1: Reflection | N1: Daily Score % | O1: Notes
A2: 46251 | B2: Monday | C2: ✓ | D2: ✓ | E2: ✓ | F2: ✓ | G2: ✓ | H2: ✓ | I2: ✓ | J2: ✓ | K2: ✗ | L2: ✓ | M2: ✓ | N2: =IF(COUNTA(C2:M2)=0,"",COUNTIF(C2:M2,"✓")/11) -> 0.90909091 | O2: Fully Motivated
A3: 46252 | B3: Tuesday | C3: ✓ | D3: ✗ | E3: ✓ | F3: ✓ | G3: ✗ | H3: ✓ | I3: ✓ | J3: ✓ | K3: ✗ | L3: ✓ | M3: ✓ | N3: =IF(COUNTA(C3:M3)=0,"",COUNTIF(C3:M3,"✓")/11) -> 0.72727273 | O3: Busy in office Work
A4: 46253 | B4: Wednesday | C4: ✗ | D4: ✓ | E4: ✓ | F4: ✓ | G4: ✓ | H4: ✓ | I4: ✓ | J4: ✓ | K4: ✓ | L4: ✓ | M4: ✓ | N4: =IF(COUNTA(C4:M4)=0,"",COUNTIF(C4:M4,"✓")/11) -> 0.90909091 | O4: Busy in office Work
A5: 46254 | B5: Thursday | C5: ✗ | D5: ✓ | E5: ✓ | F5: ✗ | G5: ✓ | H5: ✓ | I5: ✗ | J5: ✓ | K5: ✓ | L5: ✓ | M5: ✗ | N5: =IF(COUNTA(C5:M5)=0,"",COUNTIF(C5:M5,"✓")/11) -> 0.63636364 | O5: De-Motivated
A6: 46255 | B6: Friday | N6: =IF(COUNTA(C6:M6)=0,"",COUNTIF(C6:M6,"✓")/11)
A7: 46256 | B7: Saturday | N7: =IF(COUNTA(C7:M7)=0,"",COUNTIF(C7:M7,"✓")/11)
A8: 46257 | B8: Sunday | N8: =IF(COUNTA(C8:M8)=0,"",COUNTIF(C8:M8,"✓")/11)
A9: 46258 | B9: Monday | N9: =IF(COUNTA(C9:M9)=0,"",COUNTIF(C9:M9,"✓")/11)
A10: 46259 | B10: Tuesday | N10: =IF(COUNTA(C10:M10)=0,"",COUNTIF(C10:M10,"✓")/11)
A11: 46260 | B11: Wednesday | N11: =IF(COUNTA(C11:M11)=0,"",COUNTIF(C11:M11,"✓")/11)
A12: 46261 | B12: Thursday | N12: =IF(COUNTA(C12:M12)=0,"",COUNTIF(C12:M12,"✓")/11)
A13: 46262 | B13: Friday | N13: =IF(COUNTA(C13:M13)=0,"",COUNTIF(C13:M13,"✓")/11)
A14: 46263 | B14: Saturday | N14: =IF(COUNTA(C14:M14)=0,"",COUNTIF(C14:M14,"✓")/11)
A15: 46264 | B15: Sunday | N15: =IF(COUNTA(C15:M15)=0,"",COUNTIF(C15:M15,"✓")/11)
A16: 46265 | B16: Monday | N16: =IF(COUNTA(C16:M16)=0,"",COUNTIF(C16:M16,"✓")/11)
A17: 46266 | B17: Tuesday | N17: =IF(COUNTA(C17:M17)=0,"",COUNTIF(C17:M17,"✓")/11)
... A366: 46615 | B366: Monday | N366: =IF(COUNTA(C366:M366)=0,"",COUNTIF(C366:M366,"✓")/11)

Sheet Weekly Review
A1: Week Start | B1: Week | C1: Study Days | D1: Coding Days | E1: Workout Days | F1: Diet Days | G1: Avg Steps | H1: Avg Daily Score | I1: Weekly Score % | J1: Career Win | K1: Fitness Win | L1: Improve Next Week
A2: 46251 | B2: Week 1 | C2: =COUNTIF('Daily Tracker'!C2:C8,"✓") -> 2 | D2: =COUNTIF('Daily Tracker'!D2:D8,"✓") -> 3 | E2: =COUNTIF('Daily Tracker'!E2:E8,"✓") -> 4 | F2: =COUNTIF('Daily Tracker'!G2:G8,"✓") -> 3 | H2: =IFERROR(AVERAGE('Daily Tracker'!N2:N8),"") -> 0.79545455 | I2: =IF(H2="","",H2) -> 0.79545455
A3: 46258 | B3: Week 2 | C3: =COUNTIF('Daily Tracker'!C9:C15,"✓") -> 0 | D3: =COUNTIF('Daily Tracker'!D9:D15,"✓") -> 0 | E3: =COUNTIF('Daily Tracker'!E9:E15,"✓") -> 0 | F3: =COUNTIF('Daily Tracker'!G9:G15,"✓") -> 0 | H3: =IFERROR(AVERAGE('Daily Tracker'!N9:N15),"") | I3: =IF(H3="","",H3)
A4: 46265 | B4: Week 3 | C4: =COUNTIF('Daily Tracker'!C16:C22,"✓") -> 0 | D4: =COUNTIF('Daily Tracker'!D16:D22,"✓") -> 0 | E4: =COUNTIF('Daily Tracker'!E16:E22,"✓") -> 0 | F4: =COUNTIF('Daily Tracker'!G16:G22,"✓") -> 0 | H4: =IFERROR(AVERAGE('Daily Tracker'!N16:N22),"") | I4: =IF(H4="","",H4)
A5: 46272 | B5: Week 4 | C5: =COUNTIF('Daily Tracker'!C23:C29,"✓") -> 0 | D5: =COUNTIF('Daily Tracker'!D23:D29,"✓") -> 0 | E5: =COUNTIF('Daily Tracker'!E23:E29,"✓") -> 0 | F5: =COUNTIF('Daily Tracker'!G23:G29,"✓") -> 0 | H5: =IFERROR(AVERAGE('Daily Tracker'!N23:N29),"") | I5: =IF(H5="","",H5)
A6: 46279 | B6: Week 5 | C6: =COUNTIF('Daily Tracker'!C30:C36,"✓") -> 0 | D6: =COUNTIF('Daily Tracker'!D30:D36,"✓") -> 0 | E6: =COUNTIF('Daily Tracker'!E30:E36,"✓") -> 0 | F6: =COUNTIF('Daily Tracker'!G30:G36,"✓") -> 0 | H6: =IFERROR(AVERAGE('Daily Tracker'!N30:N36),"") | I6: =IF(H6="","",H6)
A7: 46286 | B7: Week 6 | C7: =COUNTIF('Daily Tracker'!C37:C43,"✓") -> 0 | D7: =COUNTIF('Daily Tracker'!D37:D43,"✓") -> 0 | E7: =COUNTIF('Daily Tracker'!E37:E43,"✓") -> 0 | F7: =COUNTIF('Daily Tracker'!G37:G43,"✓") -> 0 | H7: =IFERROR(AVERAGE('Daily Tracker'!N37:N43),"") | I7: =IF(H7="","",H7)
A8: 46293 | B8: Week 7 | C8: =COUNTIF('Daily Tracker'!C44:C50,"✓") -> 0 | D8: =COUNTIF('Daily Tracker'!D44:D50,"✓") -> 0 | E8: =COUNTIF('Daily Tracker'!E44:E50,"✓") -> 0 | F8: =COUNTIF('Daily Tracker'!G44:G50,"✓") -> 0 | H8: =IFERROR(AVERAGE('Daily Tracker'!N44:N50),"") | I8: =IF(H8="","",H8)
A9: 46300 | B9: Week 8 | C9: =COUNTIF('Daily Tracker'!C51:C57,"✓") -> 0 | D9: =COUNTIF('Daily Tracker'!D51:D57,"✓") -> 0 | E9: =COUNTIF('Daily Tracker'!E51:E57,"✓") -> 0 | F9: =COUNTIF('Daily Tracker'!G51:G57,"✓") -> 0 | H9: =IFERROR(AVERAGE('Daily Tracker'!N51:N57),"") | I9: =IF(H9="","",H9)
A10: 46307 | B10: Week 9 | C10: =COUNTIF('Daily Tracker'!C58:C64,"✓") -> 0 | D10: =COUNTIF('Daily Tracker'!D58:D64,"✓") -> 0 | E10: =COUNTIF('Daily Tracker'!E58:E64,"✓") -> 0 | F10: =COUNTIF('Daily Tracker'!G58:G64,"✓") -> 0 | H10: =IFERROR(AVERAGE('Daily Tracker'!N58:N64),"") | I10: =IF(H10="","",H10)
A11: 46314 | B11: Week 10 | C11: =COUNTIF('Daily Tracker'!C65:C71,"✓") -> 0 | D11: =COUNTIF('Daily Tracker'!D65:D71,"✓") -> 0 | E11: =COUNTIF('Daily Tracker'!E65:E71,"✓") -> 0 | F11: =COUNTIF('Daily Tracker'!G65:G71,"✓") -> 0 | H11: =IFERROR(AVERAGE('Daily Tracker'!N65:N71),"") | I11: =IF(H11="","",H11)
A12: 46321 | B12: Week 11 | C12: =COUNTIF('Daily Tracker'!C72:C78,"✓") -> 0 | D12: =COUNTIF('Daily Tracker'!D72:D78,"✓") -> 0 | E12: =COUNTIF('Daily Tracker'!E72:E78,"✓") -> 0 | F12: =COUNTIF('Daily Tracker'!G72:G78,"✓") -> 0 | H12: =IFERROR(AVERAGE('Daily Tracker'!N72:N78),"") | I12: =IF(H12="","",H12)
A13: 46328 | B13: Week 12 | C13: =COUNTIF('Daily Tracker'!C79:C85,"✓") -> 0 | D13: =COUNTIF('Daily Tracker'!D79:D85,"✓") -> 0 | E13: =COUNTIF('Daily Tracker'!E79:E85,"✓") -> 0 | F13: =COUNTIF('Daily Tracker'!G79:G85,"✓") -> 0 | H13: =IFERROR(AVERAGE('Daily Tracker'!N79:N85),"") | I13: =IF(H13="","",H13)
A14: 46335 | B14: Week 13 | C14: =COUNTIF('Daily Tracker'!C86:C92,"✓") -> 0 | D14: =COUNTIF('Daily Tracker'!D86:D92,"✓") -> 0 | E14: =COUNTIF('Daily Tracker'!E86:E92,"✓") -> 0 | F14: =COUNTIF('Daily Tracker'!G86:G92,"✓") -> 0 | H14: =IFERROR(AVERAGE('Daily Tracker'!N86:N92),"") | I14: =IF(H14="","",H14)
A15: 46342 | B15: Week 14 | C15: =COUNTIF('Daily Tracker'!C93:C99,"✓") -> 0 | D15: =COUNTIF('Daily Tracker'!D93:D99,"✓") -> 0 | E15: =COUNTIF('Daily Tracker'!E93:E99,"✓") -> 0 | F15: =COUNTIF('Daily Tracker'!G93:G99,"✓") -> 0 | H15: =IFERROR(AVERAGE('Daily Tracker'!N93:N99),"") | I15: =IF(H15="","",H15)
A16: 46349 | B16: Week 15 | C16: =COUNTIF('Daily Tracker'!C100:C106,"✓") -> 0 | D16: =COUNTIF('Daily Tracker'!D100:D106,"✓") -> 0 | E16: =COUNTIF('Daily Tracker'!E100:E106,"✓") -> 0 | F16: =COUNTIF('Daily Tracker'!G100:G106,"✓") -> 0 | H16: =IFERROR(AVERAGE('Daily Tracker'!N100:N106),"") | I16: =IF(H16="","",H16)
A17: 46356 | B17: Week 16 | C17: =COUNTIF('Daily Tracker'!C107:C113,"✓") -> 0 | D17: =COUNTIF('Daily Tracker'!D107:D113,"✓") -> 0 | E17: =COUNTIF('Daily Tracker'!E107:E113,"✓") -> 0 | F17: =COUNTIF('Daily Tracker'!G107:G113,"✓") -> 0 | H17: =IFERROR(AVERAGE('Daily Tracker'!N107:N113),"") | I17: =IF(H17="","",H17)
A18: 46363 | B18: Week 17 | C18: =COUNTIF('Daily Tracker'!C114:C120,"✓") -> 0 | D18: =COUNTIF('Daily Tracker'!D114:D120,"✓") -> 0 | E18: =COUNTIF('Daily Tracker'!E114:E120,"✓") -> 0 | F18: =COUNTIF('Daily Tracker'!G114:G120,"✓") -> 0 | H18: =IFERROR(AVERAGE('Daily Tracker'!N114:N120),"") | I18: =IF(H18="","",H18)
A19: 46370 | B19: Week 18 | C19: =COUNTIF('Daily Tracker'!C121:C127,"✓") -> 0 | D19: =COUNTIF('Daily Tracker'!D121:D127,"✓") -> 0 | E19: =COUNTIF('Daily Tracker'!E121:E127,"✓") -> 0 | F19: =COUNTIF('Daily Tracker'!G121:G127,"✓") -> 0 | H19: =IFERROR(AVERAGE('Daily Tracker'!N121:N127),"") | I19: =IF(H19="","",H19)
A20: 46377 | B20: Week 19 | C20: =COUNTIF('Daily Tracker'!C128:C134,"✓") -> 0 | D20: =COUNTIF('Daily Tracker'!D128:D134,"✓") -> 0 | E20: =COUNTIF('Daily Tracker'!E128:E134,"✓") -> 0 | F20: =COUNTIF('Daily Tracker'!G128:G134,"✓") -> 0 | H20: =IFERROR(AVERAGE('Daily Tracker'!N128:N134),"") | I20: =IF(H20="","",H20)
A21: 46384 | B21: Week 20 | C21: =COUNTIF('Daily Tracker'!C135:C141,"✓") -> 0 | D21: =COUNTIF('Daily Tracker'!D135:D141,"✓") -> 0 | E21: =COUNTIF('Daily Tracker'!E135:E141,"✓") -> 0 | F21: =COUNTIF('Daily Tracker'!G135:G141,"✓") -> 0 | H21: =IFERROR(AVERAGE('Daily Tracker'!N135:N141),"") | I21: =IF(H21="","",H21)
A22: 46391 | B22: Week 21 | C22: =COUNTIF('Daily Tracker'!C142:C148,"✓") -> 0 | D22: =COUNTIF('Daily Tracker'!D142:D148,"✓") -> 0 | E22: =COUNTIF('Daily Tracker'!E142:E148,"✓") -> 0 | F22: =COUNTIF('Daily Tracker'!G142:G148,"✓") -> 0 | H22: =IFERROR(AVERAGE('Daily Tracker'!N142:N148),"") | I22: =IF(H22="","",H22)
A23: 46398 | B23: Week 22 | C23: =COUNTIF('Daily Tracker'!C149:C155,"✓") -> 0 | D23: =COUNTIF('Daily Tracker'!D149:D155,"✓") -> 0 | E23: =COUNTIF('Daily Tracker'!E149:E155,"✓") -> 0 | F23: =COUNTIF('Daily Tracker'!G149:G155,"✓") -> 0 | H23: =IFERROR(AVERAGE('Daily Tracker'!N149:N155),"") | I23: =IF(H23="","",H23)
A24: 46405 | B24: Week 23 | C24: =COUNTIF('Daily Tracker'!C156:C162,"✓") -> 0 | D24: =COUNTIF('Daily Tracker'!D156:D162,"✓") -> 0 | E24: =COUNTIF('Daily Tracker'!E156:E162,"✓") -> 0 | F24: =COUNTIF('Daily Tracker'!G156:G162,"✓") -> 0 | H24: =IFERROR(AVERAGE('Daily Tracker'!N156:N162),"") | I24: =IF(H24="","",H24)
A25: 46412 | B25: Week 24 | C25: =COUNTIF('Daily Tracker'!C163:C169,"✓") -> 0 | D25: =COUNTIF('Daily Tracker'!D163:D169,"✓") -> 0 | E25: =COUNTIF('Daily Tracker'!E163:E169,"✓") -> 0 | F25: =COUNTIF('Daily Tracker'!G163:G169,"✓") -> 0 | H25: =IFERROR(AVERAGE('Daily Tracker'!N163:N169),"") | I25: =IF(H25="","",H25)
A26: 46419 | B26: Week 25 | C26: =COUNTIF('Daily Tracker'!C170:C176,"✓") -> 0 | D26: =COUNTIF('Daily Tracker'!D170:D176,"✓") -> 0 | E26: =COUNTIF('Daily Tracker'!E170:E176,"✓") -> 0 | F26: =COUNTIF('Daily Tracker'!G170:G176,"✓") -> 0 | H26: =IFERROR(AVERAGE('Daily Tracker'!N170:N176),"") | I26: =IF(H26="","",H26)
A27: 46426 | B27: Week 26 | C27: =COUNTIF('Daily Tracker'!C177:C183,"✓") -> 0 | D27: =COUNTIF('Daily Tracker'!D177:D183,"✓") -> 0 | E27: =COUNTIF('Daily Tracker'!E177:E183,"✓") -> 0 | F27: =COUNTIF('Daily Tracker'!G177:G183,"✓") -> 0 | H27: =IFERROR(AVERAGE('Daily Tracker'!N177:N183),"") | I27: =IF(H27="","",H27)
A28: 46433 | B28: Week 27 | C28: =COUNTIF('Daily Tracker'!C184:C190,"✓") -> 0 | D28: =COUNTIF('Daily Tracker'!D184:D190,"✓") -> 0 | E28: =COUNTIF('Daily Tracker'!E184:E190,"✓") -> 0 | F28: =COUNTIF('Daily Tracker'!G184:G190,"✓") -> 0 | H28: =IFERROR(AVERAGE('Daily Tracker'!N184:N190),"") | I28: =IF(H28="","",H28)
A29: 46440 | B29: Week 28 | C29: =COUNTIF('Daily Tracker'!C191:C197,"✓") -> 0 | D29: =COUNTIF('Daily Tracker'!D191:D197,"✓") -> 0 | E29: =COUNTIF('Daily Tracker'!E191:E197,"✓") -> 0 | F29: =COUNTIF('Daily Tracker'!G191:G197,"✓") -> 0 | H29: =IFERROR(AVERAGE('Daily Tracker'!N191:N197),"") | I29: =IF(H29="","",H29)
A30: 46447 | B30: Week 29 | C30: =COUNTIF('Daily Tracker'!C198:C204,"✓") -> 0 | D30: =COUNTIF('Daily Tracker'!D198:D204,"✓") -> 0 | E30: =COUNTIF('Daily Tracker'!E198:E204,"✓") -> 0 | F30: =COUNTIF('Daily Tracker'!G198:G204,"✓") -> 0 | H30: =IFERROR(AVERAGE('Daily Tracker'!N198:N204),"") | I30: =IF(H30="","",H30)
A31: 46454 | B31: Week 30 | C31: =COUNTIF('Daily Tracker'!C205:C211,"✓") -> 0 | D31: =COUNTIF('Daily Tracker'!D205:D211,"✓") -> 0 | E31: =COUNTIF('Daily Tracker'!E205:E211,"✓") -> 0 | F31: =COUNTIF('Daily Tracker'!G205:G211,"✓") -> 0 | H31: =IFERROR(AVERAGE('Daily Tracker'!N205:N211),"") | I31: =IF(H31="","",H31)
A32: 46461 | B32: Week 31 | C32: =COUNTIF('Daily Tracker'!C212:C218,"✓") -> 0 | D32: =COUNTIF('Daily Tracker'!D212:D218,"✓") -> 0 | E32: =COUNTIF('Daily Tracker'!E212:E218,"✓") -> 0 | F32: =COUNTIF('Daily Tracker'!G212:G218,"✓") -> 0 | H32: =IFERROR(AVERAGE('Daily Tracker'!N212:N218),"") | I32: =IF(H32="","",H32)
A33: 46468 | B33: Week 32 | C33: =COUNTIF('Daily Tracker'!C219:C225,"✓") -> 0 | D33: =COUNTIF('Daily Tracker'!D219:D225,"✓") -> 0 | E33: =COUNTIF('Daily Tracker'!E219:E225,"✓") -> 0 | F33: =COUNTIF('Daily Tracker'!G219:G225,"✓") -> 0 | H33: =IFERROR(AVERAGE('Daily Tracker'!N219:N225),"") | I33: =IF(H33="","",H33)
A34: 46475 | B34: Week 33 | C34: =COUNTIF('Daily Tracker'!C226:C232,"✓") -> 0 | D34: =COUNTIF('Daily Tracker'!D226:D232,"✓") -> 0 | E34: =COUNTIF('Daily Tracker'!E226:E232,"✓") -> 0 | F34: =COUNTIF('Daily Tracker'!G226:G232,"✓") -> 0 | H34: =IFERROR(AVERAGE('Daily Tracker'!N226:N232),"") | I34: =IF(H34="","",H34)
A35: 46482 | B35: Week 34 | C35: =COUNTIF('Daily Tracker'!C233:C239,"✓") -> 0 | D35: =COUNTIF('Daily Tracker'!D233:D239,"✓") -> 0 | E35: =COUNTIF('Daily Tracker'!E233:E239,"✓") -> 0 | F35: =COUNTIF('Daily Tracker'!G233:G239,"✓") -> 0 | H35: =IFERROR(AVERAGE('Daily Tracker'!N233:N239),"") | I35: =IF(H35="","",H35)
A36: 46489 | B36: Week 35 | C36: =COUNTIF('Daily Tracker'!C240:C246,"✓") -> 0 | D36: =COUNTIF('Daily Tracker'!D240:D246,"✓") -> 0 | E36: =COUNTIF('Daily Tracker'!E240:E246,"✓") -> 0 | F36: =COUNTIF('Daily Tracker'!G240:G246,"✓") -> 0 | H36: =IFERROR(AVERAGE('Daily Tracker'!N240:N246),"") | I36: =IF(H36="","",H36)
A37: 46496 | B37: Week 36 | C37: =COUNTIF('Daily Tracker'!C247:C253,"✓") -> 0 | D37: =COUNTIF('Daily Tracker'!D247:D253,"✓") -> 0 | E37: =COUNTIF('Daily Tracker'!E247:E253,"✓") -> 0 | F37: =COUNTIF('Daily Tracker'!G247:G253,"✓") -> 0 | H37: =IFERROR(AVERAGE('Daily Tracker'!N247:N253),"") | I37: =IF(H37="","",H37)
A38: 46503 | B38: Week 37 | C38: =COUNTIF('Daily Tracker'!C254:C260,"✓") -> 0 | D38: =COUNTIF('Daily Tracker'!D254:D260,"✓") -> 0 | E38: =COUNTIF('Daily Tracker'!E254:E260,"✓") -> 0 | F38: =COUNTIF('Daily Tracker'!G254:G260,"✓") -> 0 | H38: =IFERROR(AVERAGE('Daily Tracker'!N254:N260),"") | I38: =IF(H38="","",H38)
A39: 46510 | B39: Week 38 | C39: =COUNTIF('Daily Tracker'!C261:C267,"✓") -> 0 | D39: =COUNTIF('Daily Tracker'!D261:D267,"✓") -> 0 | E39: =COUNTIF('Daily Tracker'!E261:E267,"✓") -> 0 | F39: =COUNTIF('Daily Tracker'!G261:G267,"✓") -> 0 | H39: =IFERROR(AVERAGE('Daily Tracker'!N261:N267),"") | I39: =IF(H39="","",H39)
A40: 46517 | B40: Week 39 | C40: =COUNTIF('Daily Tracker'!C268:C274,"✓") -> 0 | D40: =COUNTIF('Daily Tracker'!D268:D274,"✓") -> 0 | E40: =COUNTIF('Daily Tracker'!E268:E274,"✓") -> 0 | F40: =COUNTIF('Daily Tracker'!G268:G274,"✓") -> 0 | H40: =IFERROR(AVERAGE('Daily Tracker'!N268:N274),"") | I40: =IF(H40="","",H40)
...

Sheet Monthly Goals
A1: Month | B1: Primary Career Skill | C1: Major Project | D1: Study Target (hrs) | E1: Projects Target | F1: Workout Target | G1: Weight Target (kg) | H1: Savings Target (₹) | I1: Job Applications | J1: Actual Study Hrs | K1: Projects Completed | L1: Workout Days | M1: Weight (kg) | N1: Savings (₹) | O1: Applications | P1: Goal Completion % | Q1: Monthly Score | R1: Key Result / Notes
A2: 46266 | D2: 50 | E2: 1 | F2: 24 | I2: 10 | P2: =IFERROR(AVERAGE(MIN(J2/D2,1),MIN(K2/E2,1),MIN(L2/F2,1),MIN(I2/I2,1)), "") -> 0.25 | Q2: =IF(P2="","",P2*100) -> 25
A3: 46296 | D3: 50 | E3: 1 | F3: 24 | I3: 10 | P3: =IFERROR(AVERAGE(MIN(J3/D3,1),MIN(K3/E3,1),MIN(L3/F3,1),MIN(I3/I3,1)), "") -> 0.25 | Q3: =IF(P3="","",P3*100) -> 25
A4: 46327 | D4: 50 | E4: 1 | F4: 24 | I4: 10 | P4: =IFERROR(AVERAGE(MIN(J4/D4,1),MIN(K4/E4,1),MIN(L4/F4,1),MIN(I4/I4,1)), "") -> 0.25 | Q4: =IF(P4="","",P4*100) -> 25
A5: 46357 | D5: 50 | E5: 1 | F5: 24 | I5: 10 | P5: =IFERROR(AVERAGE(MIN(J5/D5,1),MIN(K5/E5,1),MIN(L5/F5,1),MIN(I5/I5,1)), "") -> 0.25 | Q5: =IF(P5="","",P5*100) -> 25
A6: 46388 | D6: 50 | E6: 1 | F6: 24 | I6: 10 | P6: =IFERROR(AVERAGE(MIN(J6/D6,1),MIN(K6/E6,1),MIN(L6/F6,1),MIN(I6/I6,1)), "") -> 0.25 | Q6: =IF(P6="","",P6*100) -> 25
A7: 46419 | D7: 50 | E7: 1 | F7: 24 | I7: 10 | P7: =IFERROR(AVERAGE(MIN(J7/D7,1),MIN(K7/E7,1),MIN(L7/F7,1),MIN(I7/I7,1)), "") -> 0.25 | Q7: =IF(P7="","",P7*100) -> 25
A8: 46447 | D8: 50 | E8: 1 | F8: 24 | I8: 10 | P8: =IFERROR(AVERAGE(MIN(J8/D8,1),MIN(K8/E8,1),MIN(L8/F8,1),MIN(I8/I8,1)), "") -> 0.25 | Q8: =IF(P8="","",P8*100) -> 25
A9: 46478 | D9: 50 | E9: 1 | F9: 24 | I9: 10 | P9: =IFERROR(AVERAGE(MIN(J9/D9,1),MIN(K9/E9,1),MIN(L9/F9,1),MIN(I9/I9,1)), "") -> 0.25 | Q9: =IF(P9="","",P9*100) -> 25
A10: 46508 | D10: 50 | E10: 1 | F10: 24 | I10: 10 | P10: =IFERROR(AVERAGE(MIN(J10/D10,1),MIN(K10/E10,1),MIN(L10/F10,1),MIN(I10/I10,1)), "") -> 0.25 | Q10: =IF(P10="","",P10*100) -> 25
A11: 46539 | D11: 50 | E11: 1 | F11: 24 | I11: 10 | P11: =IFERROR(AVERAGE(MIN(J11/D11,1),MIN(K11/E11,1),MIN(L11/F11,1),MIN(I11/I11,1)), "") -> 0.25 | Q11: =IF(P11="","",P11*100) -> 25
A12: 46569 | D12: 50 | E12: 1 | F12: 24 | I12: 10 | P12: =IFERROR(AVERAGE(MIN(J12/D12,1),MIN(K12/E12,1),MIN(L12/F12,1),MIN(I12/I12,1)), "") -> 0.25 | Q12: =IF(P12="","",P12*100) -> 25
A13: 46600 | D13: 50 | E13: 1 | F13: 24 | I13: 10 | P13: =IFERROR(AVERAGE(MIN(J13/D13,1),MIN(K13/E13,1),MIN(L13/F13,1),MIN(I13/I13,1)), "") -> 0.25 | Q13: =IF(P13="","",P13*100) -> 25

Sheet Instructions
A1: How to use this tracker
A3: Daily Tracker: enter ✓ when you complete a habit and ✗ when you miss it.
A4: Daily Score is calculated automatically from the 11 daily habits.
A5: Weekly Review: review your consistency every Sunday and enter average steps and wins.
A6: Monthly Goals: set one primary career skill and one major project each month, then enter actual results.
A7: Dashboard: use it as your quick monthly snapshot.
A8: Rule: aim for consistency, not perfection. Never miss two days in a row.
